py27 develop-inst-noop: /opt/stack/keystone
py27 installed: aioeventlet==0.4,alembic==0.8.0,amqp==1.4.8,anyjson==0.3.3,Babel==2.2.0,bashate==0.3.2,beautifulsoup4==4.4.1,cffi==1.4.2,coverage==4.0.3,cryptography==1.1.2,decorator==4.0.6,discover==0.4.0,docutils==0.12,dogpile.cache==0.5.7,dogpile.core==0.4.1,enum34==1.1.2,eventlet==0.17.4,extras==0.0.3,fixtures==1.2.0,flake8==2.2.4,functools32==3.2.3.post2,futures==3.0.3,greenlet==0.4.9,hacking==0.10.2,httplib2==0.9.2,idna==2.0,ipaddress==1.0.16,iso8601==0.1.11,Jinja2==2.8,jsonschema==2.5.1,keystonemiddleware==1.5.3,kombu==3.0.32,ldappool==1.0,linecache2==1.0.0,lxml==3.5.0,Mako==1.0.3,MarkupSafe==0.23,mccabe==0.2.1,mock==1.0.1,mox3==0.7.0,msgpack-python==0.4.6,netaddr==0.7.18,netifaces==0.10.4,oauthlib==1.0.3,oslo.concurrency==1.8.2,oslo.config==1.9.3,oslo.context==0.2.0,oslo.db==1.7.3,oslo.i18n==1.5.0,oslo.log==1.0.0,oslo.messaging==1.8.3,oslo.middleware==1.0.0,oslo.policy==0.3.2,oslo.serialization==1.4.0,oslo.utils==1.4.2,oslosphinx==2.5.0,oslotest==1.5.3,passlib==1.6.5,Paste==2.0.2,PasteDeploy==1.5.2,pbr==0.11.0,pep8==1.5.7,posix-ipc==1.0.0,prettytable==0.7.2,pyasn1==0.1.9,pycadf==0.8.0,pycparser==2.14,pycrypto==2.6.1,pyflakes==0.8.1,Pygments==2.0.2,pymongo==2.9.1,pyOpenSSL==0.15.1,pysaml2==4.0.2,pysqlite==2.8.1,python-dateutil==2.4.2,python-editor==0.5,python-keystoneclient==1.3.3,python-ldap==2.4.22,python-memcached==1.57,python-mimeparse==0.1.4,python-subunit==1.2.0,pytz==2015.7,PyYAML==3.11,repoze.lru==0.6,repoze.who==2.2,requests==2.9.1,retrying==1.3.3,Routes==2.2,six==1.10.0,Sphinx==1.2.3,SQLAlchemy==0.9.10,sqlalchemy-migrate==0.9.7,sqlparse==0.1.18,stevedore==1.3.0,tempest-lib==0.4.0,Tempita==0.5.2,testrepository==0.0.20,testresources==1.0.0,testscenarios==0.5.0,testtools==1.8.1,traceback2==1.4.0,trollius==2.0,unittest2==1.1.0,waitress==0.8.10,WebOb==1.5.1,WebTest==2.0.20,wheel==0.24.0,zope.interface==4.1.3
py27 runtests: PYTHONHASHSEED='1214255047'
py27 runtests: commands[0] | bash tools/pretty_tox.sh test_v3_root
running testr
running=
OS_STDOUT_CAPTURE=${OS_STDOUT_CAPTURE:-1} \
OS_STDERR_CAPTURE=${OS_STDERR_CAPTURE:-1} \
OS_LOG_CAPTURE=${OS_LOG_CAPTURE:-1} \
${PYTHON:-python} -m subunit.run discover -t ./ ${OS_TEST_PATH:-./keystone/tests/unit} --list 
running=
OS_STDOUT_CAPTURE=${OS_STDOUT_CAPTURE:-1} \
OS_STDERR_CAPTURE=${OS_STDERR_CAPTURE:-1} \
OS_LOG_CAPTURE=${OS_LOG_CAPTURE:-1} \
${PYTHON:-python} -m subunit.run discover -t ./ ${OS_TEST_PATH:-./keystone/tests/unit}  --load-list /tmp/tmpW00LtR
{0} keystone.tests.unit.test_v3_root.IdentityTestCase.test_add_user_to_group [0.374761s] ... ok
{0} keystone.tests.unit.test_v3_root.IdentityTestCase.test_admin_password_reset [0.449962s] ... ok
{0} keystone.tests.unit.test_v3_root.IdentityTestCase.test_check_user_in_group [0.380207s] ... ok
{0} keystone.tests.unit.test_v3_root.IdentityTestCase.test_create_group [0.241989s] ... ok
{0} keystone.tests.unit.test_v3_root.IdentityTestCase.test_create_group_400 [0.238676s] ... ok
{0} keystone.tests.unit.test_v3_root.IdentityTestCase.test_create_user [0.261394s] ... ok
{0} keystone.tests.unit.test_v3_root.IdentityTestCase.test_create_user_400 [0.234429s] ... ok
{0} keystone.tests.unit.test_v3_root.IdentityTestCase.test_create_user_password_not_logged [0.340733s] ... ok
{0} keystone.tests.unit.test_v3_root.IdentityTestCase.test_delete_group [0.249685s] ... ok
{0} keystone.tests.unit.test_v3_root.IdentityTestCase.test_delete_user [0.363435s] ... ok
{0} keystone.tests.unit.test_v3_root.IdentityTestCase.test_get_group [0.242212s] ... ok
{0} keystone.tests.unit.test_v3_root.IdentityTestCase.test_get_user [0.239713s] ... ok
{0} keystone.tests.unit.test_v3_root.IdentityTestCase.test_get_user_with_default_project [0.263504s] ... ok
{0} keystone.tests.unit.test_v3_root.IdentityTestCase.test_list_groups [0.315283s] ... ok
{0} keystone.tests.unit.test_v3_root.IdentityTestCase.test_list_groups_for_user [0.421967s] ... FAILED

Captured traceback:
~~~~~~~~~~~~~~~~~~~
    Traceback (most recent call last):
      File "keystone/tests/unit/test_v3_root.py", line 196, in test_list_groups_for_user
        expected_status=exception.ForbiddenAction.code)
      File "keystone/tests/unit/test_v3.py", line 547, in get
        r = self.v3_request(method='GET', path=path, **kwargs)
      File "keystone/tests/unit/test_v3.py", line 544, in v3_request
        return self.admin_request(path=path, token=token, **kwargs)
      File "keystone/tests/unit/rest.py", line 207, in admin_request
        return self._request(app=self.admin_app, **kwargs)
      File "keystone/tests/unit/rest.py", line 196, in _request
        response = self.restful_request(**kwargs)
      File "keystone/tests/unit/rest.py", line 182, in restful_request
        **kwargs)
      File "keystone/tests/unit/rest.py", line 90, in request
        **kwargs)
      File "/opt/stack/keystone/.tox/py27/local/lib/python2.7/site-packages/webtest/app.py", line 567, in request
        expect_errors=expect_errors,
      File "/opt/stack/keystone/.tox/py27/local/lib/python2.7/site-packages/webtest/app.py", line 632, in do_request
        self._check_status(status, res)
      File "/opt/stack/keystone/.tox/py27/local/lib/python2.7/site-packages/webtest/app.py", line 667, in _check_status
        "Bad response: %s (not %s)", res_status, status)
    webtest.app.AppError: Bad response: 200 OK (not 403)
    

Captured pythonlogging:
~~~~~~~~~~~~~~~~~~~~~~~
    Adding cache-proxy 'keystone.tests.unit.test_cache.CacheIsolatingProxy' to backend.
    NeedRegenerationException
    no value, waiting for create lock
    value creation lock <dogpile.cache.region._LockWrapper object at 0x7fcaddc22310> acquired
    Calling creation function
    Released creation lock
    NeedRegenerationException
    no value, waiting for create lock
    value creation lock <dogpile.cache.region._LockWrapper object at 0x7fcadd860ad0> acquired
    Calling creation function
    Released creation lock
    NeedRegenerationException
    no value, waiting for create lock
    value creation lock <dogpile.cache.region._LockWrapper object at 0x7fcadd860ad0> acquired
    Calling creation function
    Released creation lock
    NeedRegenerationException
    no value, waiting for create lock
    value creation lock <dogpile.cache.region._LockWrapper object at 0x7fcaddc39790> acquired
    Calling creation function
    Released creation lock
    Auth token not in the request header. Will not build auth context.
    POST http://localhost:80/v3/auth/tokens
    NeedRegenerationException
    no value, waiting for create lock
    value creation lock <dogpile.cache.region._LockWrapper object at 0x7fcae01fefd0> acquired
    Calling creation function
    Released creation lock
    NeedRegenerationException
    no value, waiting for create lock
    value creation lock <dogpile.cache.region._LockWrapper object at 0x7fcae01fe4d0> acquired
    Calling creation function
    Released creation lock
    NeedRegenerationException
    no value, waiting for create lock
    value creation lock <dogpile.cache.region._LockWrapper object at 0x7fcae0506310> acquired
    Calling creation function
    Released creation lock
    NeedRegenerationException
    no value, waiting for create lock
    value creation lock <dogpile.cache.region._LockWrapper object at 0x7fcae0506ed0> acquired
    Calling creation function
    Released creation lock
    RBAC: auth_context: {'consumer_id': None, 'roles': ['admin'], 'trustor_id': None, 'token': <KeystoneToken (audit_id=XpydtEqGQgqeXogS9ieO_Q, audit_chain_id=XpydtEqGQgqeXogS9ieO_Q) at 0x7fcadda96be0>, 'trust_id': None, 'user_id': u'af52f8fbca5b48e19a286573363cd7ca', 'is_delegated_auth': False, 'project_id': '1e499669974549da80eb13fecd0c7886', 'trustee_id': None, 'access_token_id': None}
    PUT http://localhost:80/v3/groups/262d8c2b8e094bc2bacd2630b522bbc6/users/043cf4700cac4e91b6ada7750108292e
    NeedRegenerationException
    no value, waiting for create lock
    value creation lock <dogpile.cache.region._LockWrapper object at 0x7fcae0adf210> acquired
    Calling creation function
    Released creation lock
    NeedRegenerationException
    no value, waiting for create lock
    value creation lock <dogpile.cache.region._LockWrapper object at 0x7fcae0adf110> acquired
    Calling creation function
    Released creation lock
    RBAC: Authorizing identity:add_user_to_group(user_id=043cf4700cac4e91b6ada7750108292e, group_id=262d8c2b8e094bc2bacd2630b522bbc6)
    RBAC: using auth context from the request environment
    enforce identity:add_user_to_group: {'consumer_id': None, 'roles': ['admin'], 'trustor_id': None, 'token': <KeystoneToken (audit_id=XpydtEqGQgqeXogS9ieO_Q, audit_chain_id=XpydtEqGQgqeXogS9ieO_Q) at 0x7fcadda96be0>, 'trust_id': None, 'user_id': u'af52f8fbca5b48e19a286573363cd7ca', 'is_delegated_auth': False, 'project_id': '1e499669974549da80eb13fecd0c7886', 'trustee_id': None, 'access_token_id': None}
    Reloaded policy file: /opt/stack/keystone/etc/policy.json
    RBAC: Authorization granted
    Auth token not in the request header. Will not build auth context.
    POST http://localhost:80/v3/auth/tokens
    NeedRegenerationException
    no value, waiting for create lock
    value creation lock <dogpile.cache.region._LockWrapper object at 0x7fcae01fe3d0> acquired
    Calling creation function
    Released creation lock
    RBAC: Proceeding without project or domain scope
    RBAC: auth_context: {'consumer_id': None, 'trustor_id': None, 'token': <KeystoneToken (audit_id=B0d0FPX0ToqjBkTHkGzHSw, audit_chain_id=B0d0FPX0ToqjBkTHkGzHSw) at 0x7fcadf1c7e30>, 'trust_id': None, 'user_id': u'043cf4700cac4e91b6ada7750108292e', 'is_delegated_auth': False, 'trustee_id': None, 'access_token_id': None}
    GET http://localhost:80/v3/users/043cf4700cac4e91b6ada7750108292e/groups
    Auth token not in the request header. Will not build auth context.
    POST http://localhost:80/v3/auth/tokens
    NeedRegenerationException
    no value, waiting for create lock
    value creation lock <dogpile.cache.region._LockWrapper object at 0x7fcae049d050> acquired
    Calling creation function
    Released creation lock
    RBAC: auth_context: {'consumer_id': None, 'roles': ['admin'], 'trustor_id': None, 'token': <KeystoneToken (audit_id=pBb-gamhSKSHqBHJ-OzFhA, audit_chain_id=pBb-gamhSKSHqBHJ-OzFhA) at 0x7fcadff543c8>, 'trust_id': None, 'user_id': u'af52f8fbca5b48e19a286573363cd7ca', 'is_delegated_auth': False, 'project_id': '1e499669974549da80eb13fecd0c7886', 'trustee_id': None, 'access_token_id': None}
    GET http://localhost:80/v3/users/043cf4700cac4e91b6ada7750108292e/groups
    Auth token not in the request header. Will not build auth context.
    POST http://localhost:80/v3/auth/tokens
    NeedRegenerationException
    no value, waiting for create lock
    value creation lock <dogpile.cache.region._LockWrapper object at 0x7fcae07b93d0> acquired
    Calling creation function
    Released creation lock
    NeedRegenerationException
    no value, waiting for create lock
    value creation lock <dogpile.cache.region._LockWrapper object at 0x7fcae0506ed0> acquired
    Calling creation function
    Released creation lock
    RBAC: Proceeding without project or domain scope
    RBAC: auth_context: {'consumer_id': None, 'trustor_id': None, 'token': <KeystoneToken (audit_id=hWq1N4gNR4O2C0DGaxZIIA, audit_chain_id=hWq1N4gNR4O2C0DGaxZIIA) at 0x7fcae0366e30>, 'trust_id': None, 'user_id': u'724cf4eaad264af8be1e5360b3b60e09', 'is_delegated_auth': False, 'trustee_id': None, 'access_token_id': None}
    GET http://localhost:80/v3/users/043cf4700cac4e91b6ada7750108292e/groups
    
{0} keystone.tests.unit.test_v3_root.IdentityTestCase.test_list_users [0.237092s] ... ok
{0} keystone.tests.unit.test_v3_root.IdentityTestCase.test_list_users_in_group [0.288050s] ... ok
{0} keystone.tests.unit.test_v3_root.IdentityTestCase.test_list_users_no_default_project [0.264923s] ... ok
{0} keystone.tests.unit.test_v3_root.IdentityTestCase.test_list_users_with_multiple_backends [0.450272s] ... ok
{0} keystone.tests.unit.test_v3_root.IdentityTestCase.test_list_users_with_static_admin_token_and_multiple_backends [0.190340s] ... ok
{0} keystone.tests.unit.test_v3_root.IdentityTestCase.test_remove_user_from_group [0.303001s] ... ok
{0} keystone.tests.unit.test_v3_root.IdentityTestCase.test_update_group [0.236793s] ... ok
{0} keystone.tests.unit.test_v3_root.IdentityTestCase.test_update_group_domain_id [0.286836s] ... ok
{0} keystone.tests.unit.test_v3_root.IdentityTestCase.test_update_password_not_logged [0.407141s] ... ok
{0} keystone.tests.unit.test_v3_root.IdentityTestCase.test_update_user [0.280266s] ... ok
{0} keystone.tests.unit.test_v3_root.IdentityTestCase.test_update_user_domain_id [0.319729s] ... ok
{0} keystone.tests.unit.test_v3_root.IdentityV3toV2MethodsTestCase.test_v3_to_v2_user_method [0.011359s] ... ok
{0} keystone.tests.unit.test_v3_root.IdentityV3toV2MethodsTestCase.test_v3_to_v2_user_method_list [0.009053s] ... ok
{0} keystone.tests.unit.test_v3_root.UserSelfServiceChangingPasswordsTestCase.test_changing_password [0.546029s] ... ok
{0} keystone.tests.unit.test_v3_root.UserSelfServiceChangingPasswordsTestCase.test_changing_password_not_complying_policy_fails [0.336903s] ... ok
{0} keystone.tests.unit.test_v3_root.UserSelfServiceChangingPasswordsTestCase.test_changing_password_not_logged [0.525896s] ... ok
{0} keystone.tests.unit.test_v3_root.UserSelfServiceChangingPasswordsTestCase.test_changing_password_with_disabled_user_fails [0.414886s] ... ok
{0} keystone.tests.unit.test_v3_root.UserSelfServiceChangingPasswordsTestCase.test_changing_password_with_incorrect_password_fails [0.388935s] ... ok
{0} keystone.tests.unit.test_v3_root.UserSelfServiceChangingPasswordsTestCase.test_changing_password_with_last_used_password_fails [0.359015s] ... ok
{0} keystone.tests.unit.test_v3_root.UserSelfServiceChangingPasswordsTestCase.test_changing_password_with_missing_original_password_fails [0.342730s] ... ok
{0} keystone.tests.unit.test_v3_root.UserSelfServiceChangingPasswordsTestCase.test_changing_password_with_missing_password_fails [0.429640s] ... ok
{0} keystone.tests.unit.test_v3_root.UserSelfServiceChangingPasswordsTestCase.test_changing_password_with_same_password_fails [0.334674s] ... ok

==============================
Failed 1 tests - output below:
==============================

keystone.tests.unit.test_v3_root.IdentityTestCase.test_list_groups_for_user
---------------------------------------------------------------------------

Captured traceback:
~~~~~~~~~~~~~~~~~~~
    Traceback (most recent call last):
      File "keystone/tests/unit/test_v3_root.py", line 196, in test_list_groups_for_user
        expected_status=exception.ForbiddenAction.code)
      File "keystone/tests/unit/test_v3.py", line 547, in get
        r = self.v3_request(method='GET', path=path, **kwargs)
      File "keystone/tests/unit/test_v3.py", line 544, in v3_request
        return self.admin_request(path=path, token=token, **kwargs)
      File "keystone/tests/unit/rest.py", line 207, in admin_request
        return self._request(app=self.admin_app, **kwargs)
      File "keystone/tests/unit/rest.py", line 196, in _request
        response = self.restful_request(**kwargs)
      File "keystone/tests/unit/rest.py", line 182, in restful_request
        **kwargs)
      File "keystone/tests/unit/rest.py", line 90, in request
        **kwargs)
      File "/opt/stack/keystone/.tox/py27/local/lib/python2.7/site-packages/webtest/app.py", line 567, in request
        expect_errors=expect_errors,
      File "/opt/stack/keystone/.tox/py27/local/lib/python2.7/site-packages/webtest/app.py", line 632, in do_request
        self._check_status(status, res)
      File "/opt/stack/keystone/.tox/py27/local/lib/python2.7/site-packages/webtest/app.py", line 667, in _check_status
        "Bad response: %s (not %s)", res_status, status)
    webtest.app.AppError: Bad response: 200 OK (not 403)
    

Captured pythonlogging:
~~~~~~~~~~~~~~~~~~~~~~~
    Adding cache-proxy 'keystone.tests.unit.test_cache.CacheIsolatingProxy' to backend.
    NeedRegenerationException
    no value, waiting for create lock
    value creation lock <dogpile.cache.region._LockWrapper object at 0x7fcaddc22310> acquired
    Calling creation function
    Released creation lock
    NeedRegenerationException
    no value, waiting for create lock
    value creation lock <dogpile.cache.region._LockWrapper object at 0x7fcadd860ad0> acquired
    Calling creation function
    Released creation lock
    NeedRegenerationException
    no value, waiting for create lock
    value creation lock <dogpile.cache.region._LockWrapper object at 0x7fcadd860ad0> acquired
    Calling creation function
    Released creation lock
    NeedRegenerationException
    no value, waiting for create lock
    value creation lock <dogpile.cache.region._LockWrapper object at 0x7fcaddc39790> acquired
    Calling creation function
    Released creation lock
    Auth token not in the request header. Will not build auth context.
    POST http://localhost:80/v3/auth/tokens
    NeedRegenerationException
    no value, waiting for create lock
    value creation lock <dogpile.cache.region._LockWrapper object at 0x7fcae01fefd0> acquired
    Calling creation function
    Released creation lock
    NeedRegenerationException
    no value, waiting for create lock
    value creation lock <dogpile.cache.region._LockWrapper object at 0x7fcae01fe4d0> acquired
    Calling creation function
    Released creation lock
    NeedRegenerationException
    no value, waiting for create lock
    value creation lock <dogpile.cache.region._LockWrapper object at 0x7fcae0506310> acquired
    Calling creation function
    Released creation lock
    NeedRegenerationException
    no value, waiting for create lock
    value creation lock <dogpile.cache.region._LockWrapper object at 0x7fcae0506ed0> acquired
    Calling creation function
    Released creation lock
    RBAC: auth_context: {'consumer_id': None, 'roles': ['admin'], 'trustor_id': None, 'token': <KeystoneToken (audit_id=XpydtEqGQgqeXogS9ieO_Q, audit_chain_id=XpydtEqGQgqeXogS9ieO_Q) at 0x7fcadda96be0>, 'trust_id': None, 'user_id': u'af52f8fbca5b48e19a286573363cd7ca', 'is_delegated_auth': False, 'project_id': '1e499669974549da80eb13fecd0c7886', 'trustee_id': None, 'access_token_id': None}
    PUT http://localhost:80/v3/groups/262d8c2b8e094bc2bacd2630b522bbc6/users/043cf4700cac4e91b6ada7750108292e
    NeedRegenerationException
    no value, waiting for create lock
    value creation lock <dogpile.cache.region._LockWrapper object at 0x7fcae0adf210> acquired
    Calling creation function
    Released creation lock
    NeedRegenerationException
    no value, waiting for create lock
    value creation lock <dogpile.cache.region._LockWrapper object at 0x7fcae0adf110> acquired
    Calling creation function
    Released creation lock
    RBAC: Authorizing identity:add_user_to_group(user_id=043cf4700cac4e91b6ada7750108292e, group_id=262d8c2b8e094bc2bacd2630b522bbc6)
    RBAC: using auth context from the request environment
    enforce identity:add_user_to_group: {'consumer_id': None, 'roles': ['admin'], 'trustor_id': None, 'token': <KeystoneToken (audit_id=XpydtEqGQgqeXogS9ieO_Q, audit_chain_id=XpydtEqGQgqeXogS9ieO_Q) at 0x7fcadda96be0>, 'trust_id': None, 'user_id': u'af52f8fbca5b48e19a286573363cd7ca', 'is_delegated_auth': False, 'project_id': '1e499669974549da80eb13fecd0c7886', 'trustee_id': None, 'access_token_id': None}
    Reloaded policy file: /opt/stack/keystone/etc/policy.json
    RBAC: Authorization granted
    Auth token not in the request header. Will not build auth context.
    POST http://localhost:80/v3/auth/tokens
    NeedRegenerationException
    no value, waiting for create lock
    value creation lock <dogpile.cache.region._LockWrapper object at 0x7fcae01fe3d0> acquired
    Calling creation function
    Released creation lock
    RBAC: Proceeding without project or domain scope
    RBAC: auth_context: {'consumer_id': None, 'trustor_id': None, 'token': <KeystoneToken (audit_id=B0d0FPX0ToqjBkTHkGzHSw, audit_chain_id=B0d0FPX0ToqjBkTHkGzHSw) at 0x7fcadf1c7e30>, 'trust_id': None, 'user_id': u'043cf4700cac4e91b6ada7750108292e', 'is_delegated_auth': False, 'trustee_id': None, 'access_token_id': None}
    GET http://localhost:80/v3/users/043cf4700cac4e91b6ada7750108292e/groups
    Auth token not in the request header. Will not build auth context.
    POST http://localhost:80/v3/auth/tokens
    NeedRegenerationException
    no value, waiting for create lock
    value creation lock <dogpile.cache.region._LockWrapper object at 0x7fcae049d050> acquired
    Calling creation function
    Released creation lock
    RBAC: auth_context: {'consumer_id': None, 'roles': ['admin'], 'trustor_id': None, 'token': <KeystoneToken (audit_id=pBb-gamhSKSHqBHJ-OzFhA, audit_chain_id=pBb-gamhSKSHqBHJ-OzFhA) at 0x7fcadff543c8>, 'trust_id': None, 'user_id': u'af52f8fbca5b48e19a286573363cd7ca', 'is_delegated_auth': False, 'project_id': '1e499669974549da80eb13fecd0c7886', 'trustee_id': None, 'access_token_id': None}
    GET http://localhost:80/v3/users/043cf4700cac4e91b6ada7750108292e/groups
    Auth token not in the request header. Will not build auth context.
    POST http://localhost:80/v3/auth/tokens
    NeedRegenerationException
    no value, waiting for create lock
    value creation lock <dogpile.cache.region._LockWrapper object at 0x7fcae07b93d0> acquired
    Calling creation function
    Released creation lock
    NeedRegenerationException
    no value, waiting for create lock
    value creation lock <dogpile.cache.region._LockWrapper object at 0x7fcae0506ed0> acquired
    Calling creation function
    Released creation lock
    RBAC: Proceeding without project or domain scope
    RBAC: auth_context: {'consumer_id': None, 'trustor_id': None, 'token': <KeystoneToken (audit_id=hWq1N4gNR4O2C0DGaxZIIA, audit_chain_id=hWq1N4gNR4O2C0DGaxZIIA) at 0x7fcae0366e30>, 'trust_id': None, 'user_id': u'724cf4eaad264af8be1e5360b3b60e09', 'is_delegated_auth': False, 'trustee_id': None, 'access_token_id': None}
    GET http://localhost:80/v3/users/043cf4700cac4e91b6ada7750108292e/groups
    


======
Totals
======
Ran: 37 tests in 14.0000 sec.
 - Passed: 36
 - Skipped: 0
 - Expected Fail: 0
 - Unexpected Success: 0
 - Failed: 1
Sum of execute time for each test: 11.5815 sec.

==============
Worker Balance
==============
 - Worker 0 (37 tests) => 0:00:11.677929s

Slowest Tests:

Test id                                                                                                                         Runtime (s)
------------------------------------------------------------------------------------------------------------------------------  -----------
keystone.tests.unit.test_v3_root.UserSelfServiceChangingPasswordsTestCase.test_changing_password                                0.546
keystone.tests.unit.test_v3_root.UserSelfServiceChangingPasswordsTestCase.test_changing_password_not_logged                     0.526
keystone.tests.unit.test_v3_root.IdentityTestCase.test_list_users_with_multiple_backends                                        0.450
keystone.tests.unit.test_v3_root.IdentityTestCase.test_admin_password_reset                                                     0.450
keystone.tests.unit.test_v3_root.UserSelfServiceChangingPasswordsTestCase.test_changing_password_with_missing_password_fails    0.430
keystone.tests.unit.test_v3_root.IdentityTestCase.test_list_groups_for_user                                                     0.422
keystone.tests.unit.test_v3_root.UserSelfServiceChangingPasswordsTestCase.test_changing_password_with_disabled_user_fails       0.415
keystone.tests.unit.test_v3_root.IdentityTestCase.test_update_password_not_logged                                               0.407
keystone.tests.unit.test_v3_root.UserSelfServiceChangingPasswordsTestCase.test_changing_password_with_incorrect_password_fails  0.389
keystone.tests.unit.test_v3_root.IdentityTestCase.test_check_user_in_group                                                      0.380
ERROR: InvocationError: '/bin/bash tools/pretty_tox.sh test_v3_root'
___________________________________ summary ____________________________________
ERROR:   py27: commands failed
